Traceback (most recent call last):
  File "/Users/gabriele/opt/miniconda3/envs/tectonophysics/lib/python3.11/site-packages/jupyter_cache/executors/utils.py", line 58, in single_nb_execution
    executenb(
  File "/Users/gabriele/opt/miniconda3/envs/tectonophysics/lib/python3.11/site-packages/nbclient/client.py", line 1204, in execute
    return NotebookClient(nb=nb, resources=resources, km=km, **kwargs).execute()
           ^^^^^^^^^^^^^^^^^^^^^^^^^^^^^^^^^^^^^^^^^^^^^^^^^^^^^^^^^^^^^^^^^^^^^
  File "/Users/gabriele/opt/miniconda3/envs/tectonophysics/lib/python3.11/site-packages/nbclient/util.py", line 84, in wrapped
    return just_run(coro(*args, **kwargs))
           ^^^^^^^^^^^^^^^^^^^^^^^^^^^^^^^
  File "/Users/gabriele/opt/miniconda3/envs/tectonophysics/lib/python3.11/site-packages/nbclient/util.py", line 62, in just_run
    return loop.run_until_complete(coro)
           ^^^^^^^^^^^^^^^^^^^^^^^^^^^^^
  File "/Users/gabriele/opt/miniconda3/envs/tectonophysics/lib/python3.11/asyncio/base_events.py", line 650, in run_until_complete
    return future.result()
           ^^^^^^^^^^^^^^^
  File "/Users/gabriele/opt/miniconda3/envs/tectonophysics/lib/python3.11/contextlib.py", line 222, in __aexit__
    await self.gen.athrow(typ, value, traceback)
  File "/Users/gabriele/opt/miniconda3/envs/tectonophysics/lib/python3.11/site-packages/nbclient/client.py", line 608, in async_setup_kernel
    yield
  File "/Users/gabriele/opt/miniconda3/envs/tectonophysics/lib/python3.11/site-packages/nbclient/client.py", line 663, in async_execute
    await self.async_execute_cell(
  File "/Users/gabriele/opt/miniconda3/envs/tectonophysics/lib/python3.11/site-packages/nbclient/client.py", line 965, in async_execute_cell
    await self._check_raise_for_error(cell, cell_index, exec_reply)
  File "/Users/gabriele/opt/miniconda3/envs/tectonophysics/lib/python3.11/site-packages/nbclient/client.py", line 862, in _check_raise_for_error
    raise CellExecutionError.from_cell_and_msg(cell, exec_reply_content)
nbclient.exceptions.CellExecutionError: An error occurred while executing the following cell:
------------------
gammas = np.linspace(0,180,18001)    # colatitudes
zs = np.cos(gamma*dtr)               # cosine of the colatitudes

function = np.zeros(gamma.shape)     # cap function
function[gammas<alpha] = 1

N = 1000                             # maximum degree
Pns = eva_Pns(zs,N)                  # Legendre polynomial at "zs" up to "N"

truncated_function = Pns @ fn        
truncated_function_100 = Pns[:,:100] @ fn[:100]
------------------

[0;31m---------------------------------------------------------------------------[0m
[0;31mNameError[0m                                 Traceback (most recent call last)
Cell [0;32mIn[9], line 2[0m
[1;32m      1[0m gammas [38;5;241m=[39m np[38;5;241m.[39mlinspace([38;5;241m0[39m,[38;5;241m180[39m,[38;5;241m18001[39m)    [38;5;66;03m# colatitudes[39;00m
[0;32m----> 2[0m zs [38;5;241m=[39m np[38;5;241m.[39mcos([43mgamma[49m[38;5;241m*[39mdtr)               [38;5;66;03m# cosine of the colatitudes[39;00m
[1;32m      4[0m function [38;5;241m=[39m np[38;5;241m.[39mzeros(gamma[38;5;241m.[39mshape)     [38;5;66;03m# cap function[39;00m
[1;32m      5[0m function[gammas[38;5;241m<[39malpha] [38;5;241m=[39m [38;5;241m1[39m

[0;31mNameError[0m: name 'gamma' is not defined
NameError: name 'gamma' is not defined

